Traceback (most recent call last):
  File "/home/z1988135/636-dataproject/soup.py", line 92, in <module>
    data_finance, data_stock = get_info(get_ticker('facebook'))
  File "/home/z1988135/636-dataproject/soup.py", line 52, in get_ticker
    driver = webdriver.Firefox()
  File "/home/z1988135/anaconda3/envs/myenv/lib/python3.8/site-packages/selenium/webdriver/firefox/webdriver.py", line 71, in __init__
    super().__init__(command_executor=executor, options=options)
  File "/home/z1988135/anaconda3/envs/myenv/lib/python3.8/site-packages/selenium/webdriver/remote/webdriver.py", line 241, in __init__
    self.start_session(capabilities)
  File "/home/z1988135/anaconda3/envs/myenv/lib/python3.8/site-packages/selenium/webdriver/remote/webdriver.py", line 329, in start_session
    response = self.execute(Command.NEW_SESSION, caps)["value"]
  File "/home/z1988135/anaconda3/envs/myenv/lib/python3.8/site-packages/selenium/webdriver/remote/webdriver.py", line 384, in execute
    self.error_handler.check_response(response)
  File "/home/z1988135/anaconda3/envs/myenv/lib/python3.8/site-packages/selenium/webdriver/remote/errorhandler.py", line 232, in check_response
    raise exception_class(message, screen, stacktrace)
selenium.common.exceptions.WebDriverException: Message: Process unexpectedly closed with status 1

